Watching for file changes with StatReloader
Bad Request: /login/
"POST /login/ HTTP/1.1" 400 79
"POST /login/ HTTP/1.1" 200 483
"GET /admin/ HTTP/1.1" 200 3868
"GET /static/admin/css/nav_sidebar.css HTTP/1.1" 304 0
"GET /static/admin/js/nav_sidebar.js HTTP/1.1" 304 0
"GET /static/admin/css/dashboard.css HTTP/1.1" 200 380
"GET /static/admin/css/base.css HTTP/1.1" 200 19513
"GET /static/admin/css/responsive.css HTTP/1.1" 200 18575
"GET /static/admin/css/fonts.css HTTP/1.1" 200 423
"GET /static/admin/img/icon-changelink.svg HTTP/1.1" 200 380
"GET /static/admin/img/icon-addlink.svg HTTP/1.1" 200 331
"GET /static/admin/fonts/Roboto-Bold-webfont.woff HTTP/1.1" 200 86184
"GET /static/admin/fonts/Roboto-Light-webfont.woff HTTP/1.1" 200 85692
"GET /static/admin/fonts/Roboto-Regular-webfont.woff HTTP/1.1" 200 85876
Not Found: /favicon.ico
"GET /favicon.ico HTTP/1.1" 404 5342
"GET /admin/api/visitor/ HTTP/1.1" 200 6308
"GET /static/admin/css/changelists.css HTTP/1.1" 200 6932
"GET /static/admin/js/admin/RelatedObjectLookups.js HTTP/1.1" 200 5984
"GET /static/admin/js/core.js HTTP/1.1" 200 5698
"GET /static/admin/js/jquery.init.js HTTP/1.1" 200 347
"GET /static/admin/js/actions.js HTTP/1.1" 200 7872
"GET /static/admin/js/urlify.js HTTP/1.1" 200 7902
"GET /admin/jsi18n/ HTTP/1.1" 200 3343
"GET /static/admin/js/prepopulate.js HTTP/1.1" 200 1531
"GET /static/admin/js/vendor/jquery/jquery.js HTTP/1.1" 200 288580
"GET /static/admin/js/vendor/xregexp/xregexp.js HTTP/1.1" 200 232381
"GET /static/admin/img/tooltag-add.svg HTTP/1.1" 200 331
"GET /admin/api/visitor/2/change/ HTTP/1.1" 200 17246
"GET /static/admin/css/forms.css HTTP/1.1" 200 8878
"GET /static/admin/js/calendar.js HTTP/1.1" 200 8466
"GET /static/admin/js/admin/DateTimeShortcuts.js HTTP/1.1" 200 19634
"GET /admin/jsi18n/ HTTP/1.1" 200 3343
"GET /static/admin/js/prepopulate_init.js HTTP/1.1" 200 492
"GET /static/admin/css/widgets.css HTTP/1.1" 200 11097
"GET /static/admin/js/change_form.js HTTP/1.1" 200 606
"GET /static/admin/img/icon-clock.svg HTTP/1.1" 200 677
"GET /static/admin/img/icon-calendar.svg HTTP/1.1" 200 1086
"GET /admin/api/visitor/ HTTP/1.1" 200 6308
"GET /admin/api/visitor/2/change/ HTTP/1.1" 200 17246
/Users/tairsairanbekov/PycharmProjects/final/api/views/vs.py changed, reloading.
Watching for file changes with StatReloader
/Users/tairsairanbekov/PycharmProjects/final/api/views/vs.py changed, reloading.
Watching for file changes with StatReloader
Unauthorized: /visitors/
"POST /visitors/ HTTP/1.1" 401 58
/Users/tairsairanbekov/PycharmProjects/final/final/settings.py changed, reloading.
Watching for file changes with StatReloader
{'username': [ErrorDetail(string='user with this username already exists.', code='unique')]}
"POST /visitors/ HTTP/1.1" 200 56
User created
"POST /visitors/ HTTP/1.1" 200 83
/Users/tairsairanbekov/PycharmProjects/final/api/views/vs.py changed, reloading.
Watching for file changes with StatReloader
/Users/tairsairanbekov/PycharmProjects/final/api/views/vs.py changed, reloading.
Watching for file changes with StatReloader
"GET /admin/api/visitor/ HTTP/1.1" 200 6513
"GET /admin/api/visitor/4/change/ HTTP/1.1" 200 17165
"GET /admin/jsi18n/ HTTP/1.1" 200 3343
"GET /admin/api/visitor/4/delete/ HTTP/1.1" 200 4717
"GET /static/admin/js/cancel.js HTTP/1.1" 200 884
Internal Server Error: /admin/api/visitor/4/delete/
Traceback (most recent call last):
  File "/Users/tairsairanbekov/PycharmProjects/my_env/lib/python3.9/site-packages/django/db/backends/utils.py", line 89, in _execute
    return self.cursor.execute(sql, params)
  File "/Users/tairsairanbekov/PycharmProjects/my_env/lib/python3.9/site-packages/django/db/backends/sqlite3/base.py", line 477, in execute
    return Database.Cursor.execute(self, query, params)
sqlite3.OperationalError: no such table: main.api_visitor__old

The above exception was the direct cause of the following exception:

Traceback (most recent call last):
  File "/Users/tairsairanbekov/PycharmProjects/my_env/lib/python3.9/site-packages/django/core/handlers/exception.py", line 55, in inner
    response = get_response(request)
  File "/Users/tairsairanbekov/PycharmProjects/my_env/lib/python3.9/site-packages/django/core/handlers/base.py", line 197, in _get_response
    response = wrapped_callback(request, *callback_args, **callback_kwargs)
  File "/Users/tairsairanbekov/PycharmProjects/my_env/lib/python3.9/site-packages/django/contrib/admin/options.py", line 683, in wrapper
    return self.admin_site.admin_view(view)(*args, **kwargs)
  File "/Users/tairsairanbekov/PycharmProjects/my_env/lib/python3.9/site-packages/django/utils/decorators.py", line 133, in _wrapped_view
    response = view_func(request, *args, **kwargs)
  File "/Users/tairsairanbekov/PycharmProjects/my_env/lib/python3.9/site-packages/django/views/decorators/cache.py", line 62, in _wrapped_view_func
    response = view_func(request, *args, **kwargs)
  File "/Users/tairsairanbekov/PycharmProjects/my_env/lib/python3.9/site-packages/django/contrib/admin/sites.py", line 242, in inner
    return view(request, *args, **kwargs)
  File "/Users/tairsairanbekov/PycharmProjects/my_env/lib/python3.9/site-packages/django/utils/decorators.py", line 46, in _wrapper
    return bound_method(*args, **kwargs)
  File "/Users/tairsairanbekov/PycharmProjects/my_env/lib/python3.9/site-packages/django/utils/decorators.py", line 133, in _wrapped_view
    response = view_func(request, *args, **kwargs)
  File "/Users/tairsairanbekov/PycharmProjects/my_env/lib/python3.9/site-packages/django/contrib/admin/options.py", line 2104, in delete_view
    return self._delete_view(request, object_id, extra_context)
  File "/Users/tairsairanbekov/PycharmProjects/my_env/lib/python3.9/site-packages/django/contrib/admin/options.py", line 2141, in _delete_view
    self.delete_model(request, obj)
  File "/Users/tairsairanbekov/PycharmProjects/my_env/lib/python3.9/site-packages/django/contrib/admin/options.py", line 1226, in delete_model
    obj.delete()
  File "/Users/tairsairanbekov/PycharmProjects/my_env/lib/python3.9/site-packages/django/db/models/base.py", line 1094, in delete
    return collector.delete()
  File "/Users/tairsairanbekov/PycharmProjects/my_env/lib/python3.9/site-packages/django/db/models/deletion.py", line 462, in delete
    count = qs._raw_delete(using=self.using)
  File "/Users/tairsairanbekov/PycharmProjects/my_env/lib/python3.9/site-packages/django/db/models/query.py", line 843, in _raw_delete
    cursor = query.get_compiler(using).execute_sql(CURSOR)
  File "/Users/tairsairanbekov/PycharmProjects/my_env/lib/python3.9/site-packages/django/db/models/sql/compiler.py", line 1361, in execute_sql
    cursor.execute(sql, params)
  File "/Users/tairsairanbekov/PycharmProjects/my_env/lib/python3.9/site-packages/django/db/backends/utils.py", line 103, in execute
    return super().execute(sql, params)
  File "/Users/tairsairanbekov/PycharmProjects/my_env/lib/python3.9/site-packages/django/db/backends/utils.py", line 67, in execute
    return self._execute_with_wrappers(
  File "/Users/tairsairanbekov/PycharmProjects/my_env/lib/python3.9/site-packages/django/db/backends/utils.py", line 80, in _execute_with_wrappers
    return executor(sql, params, many, context)
  File "/Users/tairsairanbekov/PycharmProjects/my_env/lib/python3.9/site-packages/django/db/backends/utils.py", line 89, in _execute
    return self.cursor.execute(sql, params)
  File "/Users/tairsairanbekov/PycharmProjects/my_env/lib/python3.9/site-packages/django/db/utils.py", line 91, in __exit__
    raise dj_exc_value.with_traceback(traceback) from exc_value
  File "/Users/tairsairanbekov/PycharmProjects/my_env/lib/python3.9/site-packages/django/db/backends/utils.py", line 89, in _execute
    return self.cursor.execute(sql, params)
  File "/Users/tairsairanbekov/PycharmProjects/my_env/lib/python3.9/site-packages/django/db/backends/sqlite3/base.py", line 477, in execute
    return Database.Cursor.execute(self, query, params)
django.db.utils.OperationalError: no such table: main.api_visitor__old
"POST /admin/api/visitor/4/delete/ HTTP/1.1" 500 158186
"GET /admin/api/visitor/4/delete/ HTTP/1.1" 200 4717
"GET /admin/api/visitor/4/change/ HTTP/1.1" 200 17165
"GET /admin/api/visitor/ HTTP/1.1" 200 6513
"GET /admin/jsi18n/ HTTP/1.1" 200 3343
/Users/tairsairanbekov/PycharmProjects/final/api/views/vs.py changed, reloading.
Watching for file changes with StatReloader
/Users/tairsairanbekov/PycharmProjects/final/api/views/vs.py changed, reloading.
Watching for file changes with StatReloader
/Users/tairsairanbekov/PycharmProjects/final/api/views/vs.py changed, reloading.
Watching for file changes with StatReloader
"DELETE /visitors/1 HTTP/1.1" 301 0
Method Not Allowed: /visitors/1/
"GET /visitors/1/ HTTP/1.1" 405 40
"DELETE /visitors/1 HTTP/1.1" 301 0
Method Not Allowed: /visitors/1/
"GET /visitors/1/ HTTP/1.1" 405 40
Internal Server Error: /visitors/1/
Traceback (most recent call last):
  File "/Users/tairsairanbekov/PycharmProjects/my_env/lib/python3.9/site-packages/django/core/handlers/exception.py", line 55, in inner
    response = get_response(request)
  File "/Users/tairsairanbekov/PycharmProjects/my_env/lib/python3.9/site-packages/django/core/handlers/base.py", line 197, in _get_response
    response = wrapped_callback(request, *callback_args, **callback_kwargs)
  File "/Users/tairsairanbekov/PycharmProjects/my_env/lib/python3.9/site-packages/django/views/decorators/csrf.py", line 54, in wrapped_view
    return view_func(*args, **kwargs)
  File "/Users/tairsairanbekov/PycharmProjects/my_env/lib/python3.9/site-packages/rest_framework/viewsets.py", line 125, in view
    return self.dispatch(request, *args, **kwargs)
  File "/Users/tairsairanbekov/PycharmProjects/my_env/lib/python3.9/site-packages/rest_framework/views.py", line 509, in dispatch
    response = self.handle_exception(exc)
  File "/Users/tairsairanbekov/PycharmProjects/my_env/lib/python3.9/site-packages/rest_framework/views.py", line 469, in handle_exception
    self.raise_uncaught_exception(exc)
  File "/Users/tairsairanbekov/PycharmProjects/my_env/lib/python3.9/site-packages/rest_framework/views.py", line 480, in raise_uncaught_exception
    raise exc
  File "/Users/tairsairanbekov/PycharmProjects/my_env/lib/python3.9/site-packages/rest_framework/views.py", line 506, in dispatch
    response = handler(request, *args, **kwargs)
TypeError: destroy() got multiple values for argument 'pk'
"DELETE /visitors/1/ HTTP/1.1" 500 82624
/Users/tairsairanbekov/PycharmProjects/final/api/views/vs.py changed, reloading.
Watching for file changes with StatReloader
Internal Server Error: /visitors/1/
Traceback (most recent call last):
  File "/Users/tairsairanbekov/PycharmProjects/my_env/lib/python3.9/site-packages/django/core/handlers/exception.py", line 55, in inner
    response = get_response(request)
  File "/Users/tairsairanbekov/PycharmProjects/my_env/lib/python3.9/site-packages/django/core/handlers/base.py", line 197, in _get_response
    response = wrapped_callback(request, *callback_args, **callback_kwargs)
  File "/Users/tairsairanbekov/PycharmProjects/my_env/lib/python3.9/site-packages/django/views/decorators/csrf.py", line 54, in wrapped_view
    return view_func(*args, **kwargs)
  File "/Users/tairsairanbekov/PycharmProjects/my_env/lib/python3.9/site-packages/rest_framework/viewsets.py", line 125, in view
    return self.dispatch(request, *args, **kwargs)
  File "/Users/tairsairanbekov/PycharmProjects/my_env/lib/python3.9/site-packages/rest_framework/views.py", line 509, in dispatch
    response = self.handle_exception(exc)
  File "/Users/tairsairanbekov/PycharmProjects/my_env/lib/python3.9/site-packages/rest_framework/views.py", line 469, in handle_exception
    self.raise_uncaught_exception(exc)
  File "/Users/tairsairanbekov/PycharmProjects/my_env/lib/python3.9/site-packages/rest_framework/views.py", line 480, in raise_uncaught_exception
    raise exc
  File "/Users/tairsairanbekov/PycharmProjects/my_env/lib/python3.9/site-packages/rest_framework/views.py", line 506, in dispatch
    response = handler(request, *args, **kwargs)
TypeError: destroy() got an unexpected keyword argument 'pk'
"DELETE /visitors/1/ HTTP/1.1" 500 82636
/Users/tairsairanbekov/PycharmProjects/final/api/views/vs.py changed, reloading.
Watching for file changes with StatReloader
"GET /admin/api/visitor/4/change/ HTTP/1.1" 200 17165
"GET /admin/jsi18n/ HTTP/1.1" 200 3343
Internal Server Error: /visitors/1/
Traceback (most recent call last):
  File "/Users/tairsairanbekov/PycharmProjects/my_env/lib/python3.9/site-packages/django/core/handlers/exception.py", line 55, in inner
    response = get_response(request)
  File "/Users/tairsairanbekov/PycharmProjects/my_env/lib/python3.9/site-packages/django/core/handlers/base.py", line 197, in _get_response
    response = wrapped_callback(request, *callback_args, **callback_kwargs)
  File "/Users/tairsairanbekov/PycharmProjects/my_env/lib/python3.9/site-packages/django/views/decorators/csrf.py", line 54, in wrapped_view
    return view_func(*args, **kwargs)
  File "/Users/tairsairanbekov/PycharmProjects/my_env/lib/python3.9/site-packages/rest_framework/viewsets.py", line 125, in view
    return self.dispatch(request, *args, **kwargs)
  File "/Users/tairsairanbekov/PycharmProjects/my_env/lib/python3.9/site-packages/rest_framework/views.py", line 509, in dispatch
    response = self.handle_exception(exc)
  File "/Users/tairsairanbekov/PycharmProjects/my_env/lib/python3.9/site-packages/rest_framework/views.py", line 469, in handle_exception
    self.raise_uncaught_exception(exc)
  File "/Users/tairsairanbekov/PycharmProjects/my_env/lib/python3.9/site-packages/rest_framework/views.py", line 480, in raise_uncaught_exception
    raise exc
  File "/Users/tairsairanbekov/PycharmProjects/my_env/lib/python3.9/site-packages/rest_framework/views.py", line 506, in dispatch
    response = handler(request, *args, **kwargs)
TypeError: destroy() got multiple values for argument 'pk'
"DELETE /visitors/1/ HTTP/1.1" 500 82624
/Users/tairsairanbekov/PycharmProjects/final/api/views/vs.py changed, reloading.
Watching for file changes with StatReloader
Not Found: /visitors/1/
"DELETE /visitors/1/ HTTP/1.1" 404 5005
/Users/tairsairanbekov/PycharmProjects/final/api/views/vs.py changed, reloading.
Watching for file changes with StatReloader
/Users/tairsairanbekov/PycharmProjects/final/api/views/vs.py changed, reloading.
Watching for file changes with StatReloader
Internal Server Error: /visitors/1/
Traceback (most recent call last):
  File "/Users/tairsairanbekov/PycharmProjects/my_env/lib/python3.9/site-packages/django/db/backends/utils.py", line 89, in _execute
    return self.cursor.execute(sql, params)
  File "/Users/tairsairanbekov/PycharmProjects/my_env/lib/python3.9/site-packages/django/db/backends/sqlite3/base.py", line 477, in execute
    return Database.Cursor.execute(self, query, params)
sqlite3.OperationalError: no such table: main.api_visitor__old

The above exception was the direct cause of the following exception:

Traceback (most recent call last):
  File "/Users/tairsairanbekov/PycharmProjects/my_env/lib/python3.9/site-packages/django/core/handlers/exception.py", line 55, in inner
    response = get_response(request)
  File "/Users/tairsairanbekov/PycharmProjects/my_env/lib/python3.9/site-packages/django/core/handlers/base.py", line 197, in _get_response
    response = wrapped_callback(request, *callback_args, **callback_kwargs)
  File "/Users/tairsairanbekov/PycharmProjects/my_env/lib/python3.9/site-packages/django/views/decorators/csrf.py", line 54, in wrapped_view
    return view_func(*args, **kwargs)
  File "/Users/tairsairanbekov/PycharmProjects/my_env/lib/python3.9/site-packages/rest_framework/viewsets.py", line 125, in view
    return self.dispatch(request, *args, **kwargs)
  File "/Users/tairsairanbekov/PycharmProjects/my_env/lib/python3.9/site-packages/rest_framework/views.py", line 509, in dispatch
    response = self.handle_exception(exc)
  File "/Users/tairsairanbekov/PycharmProjects/my_env/lib/python3.9/site-packages/rest_framework/views.py", line 469, in handle_exception
    self.raise_uncaught_exception(exc)
  File "/Users/tairsairanbekov/PycharmProjects/my_env/lib/python3.9/site-packages/rest_framework/views.py", line 480, in raise_uncaught_exception
    raise exc
  File "/Users/tairsairanbekov/PycharmProjects/my_env/lib/python3.9/site-packages/rest_framework/views.py", line 506, in dispatch
    response = handler(request, *args, **kwargs)
  File "/Users/tairsairanbekov/PycharmProjects/final/api/views/vs.py", line 41, in destroy
    user.delete()
  File "/Users/tairsairanbekov/PycharmProjects/my_env/lib/python3.9/site-packages/django/db/models/base.py", line 1094, in delete
    return collector.delete()
  File "/Users/tairsairanbekov/PycharmProjects/my_env/lib/python3.9/site-packages/django/db/models/deletion.py", line 462, in delete
    count = qs._raw_delete(using=self.using)
  File "/Users/tairsairanbekov/PycharmProjects/my_env/lib/python3.9/site-packages/django/db/models/query.py", line 843, in _raw_delete
    cursor = query.get_compiler(using).execute_sql(CURSOR)
  File "/Users/tairsairanbekov/PycharmProjects/my_env/lib/python3.9/site-packages/django/db/models/sql/compiler.py", line 1361, in execute_sql
    cursor.execute(sql, params)
  File "/Users/tairsairanbekov/PycharmProjects/my_env/lib/python3.9/site-packages/django/db/backends/utils.py", line 103, in execute
    return super().execute(sql, params)
  File "/Users/tairsairanbekov/PycharmProjects/my_env/lib/python3.9/site-packages/django/db/backends/utils.py", line 67, in execute
    return self._execute_with_wrappers(
  File "/Users/tairsairanbekov/PycharmProjects/my_env/lib/python3.9/site-packages/django/db/backends/utils.py", line 80, in _execute_with_wrappers
    return executor(sql, params, many, context)
  File "/Users/tairsairanbekov/PycharmProjects/my_env/lib/python3.9/site-packages/django/db/backends/utils.py", line 89, in _execute
    return self.cursor.execute(sql, params)
  File "/Users/tairsairanbekov/PycharmProjects/my_env/lib/python3.9/site-packages/django/db/utils.py", line 91, in __exit__
    raise dj_exc_value.with_traceback(traceback) from exc_value
  File "/Users/tairsairanbekov/PycharmProjects/my_env/lib/python3.9/site-packages/django/db/backends/utils.py", line 89, in _execute
    return self.cursor.execute(sql, params)
  File "/Users/tairsairanbekov/PycharmProjects/my_env/lib/python3.9/site-packages/django/db/backends/sqlite3/base.py", line 477, in execute
    return Database.Cursor.execute(self, query, params)
django.db.utils.OperationalError: no such table: main.api_visitor__old
"DELETE /visitors/1/ HTTP/1.1" 500 143612
Internal Server Error: /visitors/1/
Traceback (most recent call last):
  File "/Users/tairsairanbekov/PycharmProjects/my_env/lib/python3.9/site-packages/django/db/backends/utils.py", line 89, in _execute
    return self.cursor.execute(sql, params)
  File "/Users/tairsairanbekov/PycharmProjects/my_env/lib/python3.9/site-packages/django/db/backends/sqlite3/base.py", line 477, in execute
    return Database.Cursor.execute(self, query, params)
sqlite3.OperationalError: no such table: main.api_visitor__old

The above exception was the direct cause of the following exception:

Traceback (most recent call last):
  File "/Users/tairsairanbekov/PycharmProjects/my_env/lib/python3.9/site-packages/django/core/handlers/exception.py", line 55, in inner
    response = get_response(request)
  File "/Users/tairsairanbekov/PycharmProjects/my_env/lib/python3.9/site-packages/django/core/handlers/base.py", line 197, in _get_response
    response = wrapped_callback(request, *callback_args, **callback_kwargs)
  File "/Users/tairsairanbekov/PycharmProjects/my_env/lib/python3.9/site-packages/django/views/decorators/csrf.py", line 54, in wrapped_view
    return view_func(*args, **kwargs)
  File "/Users/tairsairanbekov/PycharmProjects/my_env/lib/python3.9/site-packages/rest_framework/viewsets.py", line 125, in view
    return self.dispatch(request, *args, **kwargs)
  File "/Users/tairsairanbekov/PycharmProjects/my_env/lib/python3.9/site-packages/rest_framework/views.py", line 509, in dispatch
    response = self.handle_exception(exc)
  File "/Users/tairsairanbekov/PycharmProjects/my_env/lib/python3.9/site-packages/rest_framework/views.py", line 469, in handle_exception
    self.raise_uncaught_exception(exc)
  File "/Users/tairsairanbekov/PycharmProjects/my_env/lib/python3.9/site-packages/rest_framework/views.py", line 480, in raise_uncaught_exception
    raise exc
  File "/Users/tairsairanbekov/PycharmProjects/my_env/lib/python3.9/site-packages/rest_framework/views.py", line 506, in dispatch
    response = handler(request, *args, **kwargs)
  File "/Users/tairsairanbekov/PycharmProjects/final/api/views/vs.py", line 41, in destroy
    user.delete()
  File "/Users/tairsairanbekov/PycharmProjects/my_env/lib/python3.9/site-packages/django/db/models/base.py", line 1094, in delete
    return collector.delete()
  File "/Users/tairsairanbekov/PycharmProjects/my_env/lib/python3.9/site-packages/django/db/models/deletion.py", line 462, in delete
    count = qs._raw_delete(using=self.using)
  File "/Users/tairsairanbekov/PycharmProjects/my_env/lib/python3.9/site-packages/django/db/models/query.py", line 843, in _raw_delete
    cursor = query.get_compiler(using).execute_sql(CURSOR)
  File "/Users/tairsairanbekov/PycharmProjects/my_env/lib/python3.9/site-packages/django/db/models/sql/compiler.py", line 1361, in execute_sql
    cursor.execute(sql, params)
  File "/Users/tairsairanbekov/PycharmProjects/my_env/lib/python3.9/site-packages/django/db/backends/utils.py", line 103, in execute
    return super().execute(sql, params)
  File "/Users/tairsairanbekov/PycharmProjects/my_env/lib/python3.9/site-packages/django/db/backends/utils.py", line 67, in execute
    return self._execute_with_wrappers(
  File "/Users/tairsairanbekov/PycharmProjects/my_env/lib/python3.9/site-packages/django/db/backends/utils.py", line 80, in _execute_with_wrappers
    return executor(sql, params, many, context)
  File "/Users/tairsairanbekov/PycharmProjects/my_env/lib/python3.9/site-packages/django/db/backends/utils.py", line 89, in _execute
    return self.cursor.execute(sql, params)
  File "/Users/tairsairanbekov/PycharmProjects/my_env/lib/python3.9/site-packages/django/db/utils.py", line 91, in __exit__
    raise dj_exc_value.with_traceback(traceback) from exc_value
  File "/Users/tairsairanbekov/PycharmProjects/my_env/lib/python3.9/site-packages/django/db/backends/utils.py", line 89, in _execute
    return self.cursor.execute(sql, params)
  File "/Users/tairsairanbekov/PycharmProjects/my_env/lib/python3.9/site-packages/django/db/backends/sqlite3/base.py", line 477, in execute
    return Database.Cursor.execute(self, query, params)
django.db.utils.OperationalError: no such table: main.api_visitor__old
"DELETE /visitors/1/ HTTP/1.1" 500 143612
Internal Server Error: /visitors/
Traceback (most recent call last):
  File "/Users/tairsairanbekov/PycharmProjects/my_env/lib/python3.9/site-packages/django/core/handlers/exception.py", line 55, in inner
    response = get_response(request)
  File "/Users/tairsairanbekov/PycharmProjects/my_env/lib/python3.9/site-packages/django/core/handlers/base.py", line 197, in _get_response
    response = wrapped_callback(request, *callback_args, **callback_kwargs)
  File "/Users/tairsairanbekov/PycharmProjects/my_env/lib/python3.9/site-packages/django/views/decorators/csrf.py", line 54, in wrapped_view
    return view_func(*args, **kwargs)
  File "/Users/tairsairanbekov/PycharmProjects/my_env/lib/python3.9/site-packages/rest_framework/viewsets.py", line 125, in view
    return self.dispatch(request, *args, **kwargs)
  File "/Users/tairsairanbekov/PycharmProjects/my_env/lib/python3.9/site-packages/rest_framework/views.py", line 509, in dispatch
    response = self.handle_exception(exc)
  File "/Users/tairsairanbekov/PycharmProjects/my_env/lib/python3.9/site-packages/rest_framework/views.py", line 469, in handle_exception
    self.raise_uncaught_exception(exc)
  File "/Users/tairsairanbekov/PycharmProjects/my_env/lib/python3.9/site-packages/rest_framework/views.py", line 480, in raise_uncaught_exception
    raise exc
  File "/Users/tairsairanbekov/PycharmProjects/my_env/lib/python3.9/site-packages/rest_framework/views.py", line 506, in dispatch
    response = handler(request, *args, **kwargs)
  File "/Users/tairsairanbekov/PycharmProjects/final/api/views/vs.py", line 30, in create
    data.password = make_password(data.password)
AttributeError: 'dict' object has no attribute 'password'
"POST /visitors/ HTTP/1.1" 500 86430
/Users/tairsairanbekov/PycharmProjects/final/api/views/vs.py changed, reloading.
Watching for file changes with StatReloader
User created
"POST /visitors/ HTTP/1.1" 200 162
Unauthorized: /login/
"POST /login/ HTTP/1.1" 401 63
"POST /login/ HTTP/1.1" 200 483
"GET /admin/api/visitor/ HTTP/1.1" 200 6310
"GET /admin/jsi18n/ HTTP/1.1" 200 3343
"GET /admin/api/visitor/5/change/ HTTP/1.1" 200 17244
"GET /admin/jsi18n/ HTTP/1.1" 200 3343
"GET /admin/logout/ HTTP/1.1" 200 1530
"GET /admin/ HTTP/1.1" 302 0
"GET /admin/login/?next=/admin/ HTTP/1.1" 200 2215
"GET /static/admin/css/login.css HTTP/1.1" 200 954
"POST /admin/login/?next=/admin/ HTTP/1.1" 200 2378
"POST /admin/login/?next=/admin/ HTTP/1.1" 200 2378
"POST /admin/login/?next=/admin/ HTTP/1.1" 200 2378
"POST /login/ HTTP/1.1" 200 483
"POST /admin/login/?next=/admin/ HTTP/1.1" 302 0
"GET /admin/ HTTP/1.1" 200 3868
"GET /admin/api/visitor/ HTTP/1.1" 200 6310
"GET /admin/jsi18n/ HTTP/1.1" 200 3343
"GET /admin/api/visitor/5/change/ HTTP/1.1" 200 17244
"GET /admin/jsi18n/ HTTP/1.1" 200 3343
/Users/tairsairanbekov/PycharmProjects/final/api/models.py changed, reloading.
Watching for file changes with StatReloader
Watching for file changes with StatReloader
/Users/tairsairanbekov/PycharmProjects/final/api/views/cbv.py changed, reloading.
Watching for file changes with StatReloader
Bad Request: /blogs/
"POST /blogs/ HTTP/1.1" 400 107
"POST /blogs/ HTTP/1.1" 201 85
Unauthorized: /blogs/1/
"PATCH /blogs/1/ HTTP/1.1" 401 58
"POST /login/ HTTP/1.1" 200 483
Unauthorized: /blogs/1/
"PATCH /blogs/1/ HTTP/1.1" 401 58
Method Not Allowed: /blogs/1/
"PATCH /blogs/1/ HTTP/1.1" 405 42
"PUT /blogs/1/ HTTP/1.1" 200 50
/Users/tairsairanbekov/PycharmProjects/final/api/views/cbv.py changed, reloading.
Watching for file changes with StatReloader
/Users/tairsairanbekov/PycharmProjects/final/api/views/cbv.py changed, reloading.
Watching for file changes with StatReloader
/Users/tairsairanbekov/PycharmProjects/final/api/views/cbv.py changed, reloading.
Watching for file changes with StatReloader
/Users/tairsairanbekov/PycharmProjects/final/api/views/fbv.py changed, reloading.
Watching for file changes with StatReloader
/Users/tairsairanbekov/PycharmProjects/final/api/models.py changed, reloading.
Watching for file changes with StatReloader
Internal Server Error: /
Traceback (most recent call last):
  File "/Users/tairsairanbekov/PycharmProjects/my_env/lib/python3.9/site-packages/django/db/backends/utils.py", line 89, in _execute
    return self.cursor.execute(sql, params)
  File "/Users/tairsairanbekov/PycharmProjects/my_env/lib/python3.9/site-packages/django/db/backends/sqlite3/base.py", line 477, in execute
    return Database.Cursor.execute(self, query, params)
sqlite3.OperationalError: no such column: api_visitor.image

The above exception was the direct cause of the following exception:

Traceback (most recent call last):
  File "/Users/tairsairanbekov/PycharmProjects/my_env/lib/python3.9/site-packages/django/core/handlers/exception.py", line 55, in inner
    response = get_response(request)
  File "/Users/tairsairanbekov/PycharmProjects/my_env/lib/python3.9/site-packages/django/core/handlers/base.py", line 197, in _get_response
    response = wrapped_callback(request, *callback_args, **callback_kwargs)
  File "/Users/tairsairanbekov/PycharmProjects/my_env/lib/python3.9/site-packages/django/views/decorators/csrf.py", line 54, in wrapped_view
    return view_func(*args, **kwargs)
  File "/Users/tairsairanbekov/PycharmProjects/my_env/lib/python3.9/site-packages/django/views/generic/base.py", line 84, in view
    return self.dispatch(request, *args, **kwargs)
  File "/Users/tairsairanbekov/PycharmProjects/my_env/lib/python3.9/site-packages/rest_framework/views.py", line 509, in dispatch
    response = self.handle_exception(exc)
  File "/Users/tairsairanbekov/PycharmProjects/my_env/lib/python3.9/site-packages/rest_framework/views.py", line 469, in handle_exception
    self.raise_uncaught_exception(exc)
  File "/Users/tairsairanbekov/PycharmProjects/my_env/lib/python3.9/site-packages/rest_framework/views.py", line 480, in raise_uncaught_exception
    raise exc
  File "/Users/tairsairanbekov/PycharmProjects/my_env/lib/python3.9/site-packages/rest_framework/views.py", line 497, in dispatch
    self.initial(request, *args, **kwargs)
  File "/Users/tairsairanbekov/PycharmProjects/my_env/lib/python3.9/site-packages/rest_framework/views.py", line 414, in initial
    self.perform_authentication(request)
  File "/Users/tairsairanbekov/PycharmProjects/my_env/lib/python3.9/site-packages/rest_framework/views.py", line 324, in perform_authentication
    request.user
  File "/Users/tairsairanbekov/PycharmProjects/my_env/lib/python3.9/site-packages/rest_framework/request.py", line 227, in user
    self._authenticate()
  File "/Users/tairsairanbekov/PycharmProjects/my_env/lib/python3.9/site-packages/rest_framework/request.py", line 380, in _authenticate
    user_auth_tuple = authenticator.authenticate(self)
  File "/Users/tairsairanbekov/PycharmProjects/my_env/lib/python3.9/site-packages/rest_framework/authentication.py", line 127, in authenticate
    if not user or not user.is_active:
  File "/Users/tairsairanbekov/PycharmProjects/my_env/lib/python3.9/site-packages/django/utils/functional.py", line 258, in inner
    self._setup()
  File "/Users/tairsairanbekov/PycharmProjects/my_env/lib/python3.9/site-packages/django/utils/functional.py", line 398, in _setup
    self._wrapped = self._setupfunc()
  File "/Users/tairsairanbekov/PycharmProjects/my_env/lib/python3.9/site-packages/django/contrib/auth/middleware.py", line 25, in <lambda>
    request.user = SimpleLazyObject(lambda: get_user(request))
  File "/Users/tairsairanbekov/PycharmProjects/my_env/lib/python3.9/site-packages/django/contrib/auth/middleware.py", line 11, in get_user
    request._cached_user = auth.get_user(request)
  File "/Users/tairsairanbekov/PycharmProjects/my_env/lib/python3.9/site-packages/django/contrib/auth/__init__.py", line 198, in get_user
    user = backend.get_user(user_id)
  File "/Users/tairsairanbekov/PycharmProjects/my_env/lib/python3.9/site-packages/django/contrib/auth/backends.py", line 158, in get_user
    user = UserModel._default_manager.get(pk=user_id)
  File "/Users/tairsairanbekov/PycharmProjects/my_env/lib/python3.9/site-packages/django/db/models/manager.py", line 85, in manager_method
    return getattr(self.get_queryset(), name)(*args, **kwargs)
  File "/Users/tairsairanbekov/PycharmProjects/my_env/lib/python3.9/site-packages/django/db/models/query.py", line 492, in get
    num = len(clone)
  File "/Users/tairsairanbekov/PycharmProjects/my_env/lib/python3.9/site-packages/django/db/models/query.py", line 302, in __len__
    self._fetch_all()
  File "/Users/tairsairanbekov/PycharmProjects/my_env/lib/python3.9/site-packages/django/db/models/query.py", line 1507, in _fetch_all
    self._result_cache = list(self._iterable_class(self))
  File "/Users/tairsairanbekov/PycharmProjects/my_env/lib/python3.9/site-packages/django/db/models/query.py", line 57, in __iter__
    results = compiler.execute_sql(
  File "/Users/tairsairanbekov/PycharmProjects/my_env/lib/python3.9/site-packages/django/db/models/sql/compiler.py", line 1361, in execute_sql
    cursor.execute(sql, params)
  File "/Users/tairsairanbekov/PycharmProjects/my_env/lib/python3.9/site-packages/django/db/backends/utils.py", line 103, in execute
    return super().execute(sql, params)
  File "/Users/tairsairanbekov/PycharmProjects/my_env/lib/python3.9/site-packages/django/db/backends/utils.py", line 67, in execute
    return self._execute_with_wrappers(
  File "/Users/tairsairanbekov/PycharmProjects/my_env/lib/python3.9/site-packages/django/db/backends/utils.py", line 80, in _execute_with_wrappers
    return executor(sql, params, many, context)
  File "/Users/tairsairanbekov/PycharmProjects/my_env/lib/python3.9/site-packages/django/db/backends/utils.py", line 89, in _execute
    return self.cursor.execute(sql, params)
  File "/Users/tairsairanbekov/PycharmProjects/my_env/lib/python3.9/site-packages/django/db/utils.py", line 91, in __exit__
    raise dj_exc_value.with_traceback(traceback) from exc_value
  File "/Users/tairsairanbekov/PycharmProjects/my_env/lib/python3.9/site-packages/django/db/backends/utils.py", line 89, in _execute
    return self.cursor.execute(sql, params)
  File "/Users/tairsairanbekov/PycharmProjects/my_env/lib/python3.9/site-packages/django/db/backends/sqlite3/base.py", line 477, in execute
    return Database.Cursor.execute(self, query, params)
django.db.utils.OperationalError: no such column: api_visitor.image
"GET / HTTP/1.1" 500 196773
Internal Server Error: /admin/
Traceback (most recent call last):
  File "/Users/tairsairanbekov/PycharmProjects/my_env/lib/python3.9/site-packages/django/db/backends/utils.py", line 89, in _execute
    return self.cursor.execute(sql, params)
  File "/Users/tairsairanbekov/PycharmProjects/my_env/lib/python3.9/site-packages/django/db/backends/sqlite3/base.py", line 477, in execute
    return Database.Cursor.execute(self, query, params)
sqlite3.OperationalError: no such column: api_visitor.image

The above exception was the direct cause of the following exception:

Traceback (most recent call last):
  File "/Users/tairsairanbekov/PycharmProjects/my_env/lib/python3.9/site-packages/django/core/handlers/exception.py", line 55, in inner
    response = get_response(request)
  File "/Users/tairsairanbekov/PycharmProjects/my_env/lib/python3.9/site-packages/django/core/handlers/base.py", line 197, in _get_response
    response = wrapped_callback(request, *callback_args, **callback_kwargs)
  File "/Users/tairsairanbekov/PycharmProjects/my_env/lib/python3.9/site-packages/django/contrib/admin/sites.py", line 261, in wrapper
    return self.admin_view(view, cacheable)(*args, **kwargs)
  File "/Users/tairsairanbekov/PycharmProjects/my_env/lib/python3.9/site-packages/django/utils/decorators.py", line 133, in _wrapped_view
    response = view_func(request, *args, **kwargs)
  File "/Users/tairsairanbekov/PycharmProjects/my_env/lib/python3.9/site-packages/django/views/decorators/cache.py", line 62, in _wrapped_view_func
    response = view_func(request, *args, **kwargs)
  File "/Users/tairsairanbekov/PycharmProjects/my_env/lib/python3.9/site-packages/django/contrib/admin/sites.py", line 230, in inner
    if not self.has_permission(request):
  File "/Users/tairsairanbekov/PycharmProjects/my_env/lib/python3.9/site-packages/django/contrib/admin/sites.py", line 203, in has_permission
    return request.user.is_active and request.user.is_staff
  File "/Users/tairsairanbekov/PycharmProjects/my_env/lib/python3.9/site-packages/django/utils/functional.py", line 258, in inner
    self._setup()
  File "/Users/tairsairanbekov/PycharmProjects/my_env/lib/python3.9/site-packages/django/utils/functional.py", line 398, in _setup
    self._wrapped = self._setupfunc()
  File "/Users/tairsairanbekov/PycharmProjects/my_env/lib/python3.9/site-packages/django/contrib/auth/middleware.py", line 25, in <lambda>
    request.user = SimpleLazyObject(lambda: get_user(request))
  File "/Users/tairsairanbekov/PycharmProjects/my_env/lib/python3.9/site-packages/django/contrib/auth/middleware.py", line 11, in get_user
    request._cached_user = auth.get_user(request)
  File "/Users/tairsairanbekov/PycharmProjects/my_env/lib/python3.9/site-packages/django/contrib/auth/__init__.py", line 198, in get_user
    user = backend.get_user(user_id)
  File "/Users/tairsairanbekov/PycharmProjects/my_env/lib/python3.9/site-packages/django/contrib/auth/backends.py", line 158, in get_user
    user = UserModel._default_manager.get(pk=user_id)
  File "/Users/tairsairanbekov/PycharmProjects/my_env/lib/python3.9/site-packages/django/db/models/manager.py", line 85, in manager_method
    return getattr(self.get_queryset(), name)(*args, **kwargs)
  File "/Users/tairsairanbekov/PycharmProjects/my_env/lib/python3.9/site-packages/django/db/models/query.py", line 492, in get
    num = len(clone)
  File "/Users/tairsairanbekov/PycharmProjects/my_env/lib/python3.9/site-packages/django/db/models/query.py", line 302, in __len__
    self._fetch_all()
  File "/Users/tairsairanbekov/PycharmProjects/my_env/lib/python3.9/site-packages/django/db/models/query.py", line 1507, in _fetch_all
    self._result_cache = list(self._iterable_class(self))
  File "/Users/tairsairanbekov/PycharmProjects/my_env/lib/python3.9/site-packages/django/db/models/query.py", line 57, in __iter__
    results = compiler.execute_sql(
  File "/Users/tairsairanbekov/PycharmProjects/my_env/lib/python3.9/site-packages/django/db/models/sql/compiler.py", line 1361, in execute_sql
    cursor.execute(sql, params)
  File "/Users/tairsairanbekov/PycharmProjects/my_env/lib/python3.9/site-packages/django/db/backends/utils.py", line 103, in execute
    return super().execute(sql, params)
  File "/Users/tairsairanbekov/PycharmProjects/my_env/lib/python3.9/site-packages/django/db/backends/utils.py", line 67, in execute
    return self._execute_with_wrappers(
  File "/Users/tairsairanbekov/PycharmProjects/my_env/lib/python3.9/site-packages/django/db/backends/utils.py", line 80, in _execute_with_wrappers
    return executor(sql, params, many, context)
  File "/Users/tairsairanbekov/PycharmProjects/my_env/lib/python3.9/site-packages/django/db/backends/utils.py", line 89, in _execute
    return self.cursor.execute(sql, params)
  File "/Users/tairsairanbekov/PycharmProjects/my_env/lib/python3.9/site-packages/django/db/utils.py", line 91, in __exit__
    raise dj_exc_value.with_traceback(traceback) from exc_value
  File "/Users/tairsairanbekov/PycharmProjects/my_env/lib/python3.9/site-packages/django/db/backends/utils.py", line 89, in _execute
    return self.cursor.execute(sql, params)
  File "/Users/tairsairanbekov/PycharmProjects/my_env/lib/python3.9/site-packages/django/db/backends/sqlite3/base.py", line 477, in execute
    return Database.Cursor.execute(self, query, params)
django.db.utils.OperationalError: no such column: api_visitor.image
"GET /admin/ HTTP/1.1" 500 172517
Watching for file changes with StatReloader
"GET / HTTP/1.1" 200 136
"GET /admin/ HTTP/1.1" 200 3868
"GET /static/admin/css/base.css HTTP/1.1" 304 0
"GET /static/admin/css/nav_sidebar.css HTTP/1.1" 304 0
"GET /static/admin/css/responsive.css HTTP/1.1" 304 0
"GET /static/admin/css/dashboard.css HTTP/1.1" 304 0
"GET /static/admin/css/fonts.css HTTP/1.1" 304 0
"GET /static/admin/js/nav_sidebar.js HTTP/1.1" 304 0
"GET /static/admin/img/icon-addlink.svg HTTP/1.1" 304 0
"GET /static/admin/img/icon-changelink.svg HTTP/1.1" 304 0
"GET /static/admin/fonts/Roboto-Bold-webfont.woff HTTP/1.1" 304 0
"GET /static/admin/fonts/Roboto-Light-webfont.woff HTTP/1.1" 304 0
"GET /static/admin/fonts/Roboto-Regular-webfont.woff HTTP/1.1" 304 0
"GET /admin/api/visitor/ HTTP/1.1" 200 6310
"GET /static/admin/js/vendor/jquery/jquery.js HTTP/1.1" 304 0
"GET /static/admin/css/changelists.css HTTP/1.1" 304 0
"GET /static/admin/js/jquery.init.js HTTP/1.1" 304 0
"GET /static/admin/js/core.js HTTP/1.1" 304 0
"GET /static/admin/js/admin/RelatedObjectLookups.js HTTP/1.1" 304 0
"GET /static/admin/js/actions.js HTTP/1.1" 304 0
"GET /static/admin/js/urlify.js HTTP/1.1" 304 0
"GET /static/admin/js/prepopulate.js HTTP/1.1" 304 0
"GET /static/admin/js/vendor/xregexp/xregexp.js HTTP/1.1" 304 0
"GET /admin/jsi18n/ HTTP/1.1" 200 3343
"GET /static/admin/img/tooltag-add.svg HTTP/1.1" 304 0
"GET /admin/api/visitor/1/change/ HTTP/1.1" 200 17802
"GET /static/admin/css/forms.css HTTP/1.1" 304 0
"GET /static/admin/js/admin/DateTimeShortcuts.js HTTP/1.1" 304 0
"GET /static/admin/js/calendar.js HTTP/1.1" 304 0
"GET /admin/jsi18n/ HTTP/1.1" 200 3343
"GET /static/admin/css/widgets.css HTTP/1.1" 304 0
"GET /static/admin/js/prepopulate_init.js HTTP/1.1" 304 0
"GET /static/admin/js/change_form.js HTTP/1.1" 304 0
"GET /static/admin/img/icon-calendar.svg HTTP/1.1" 304 0
"GET /static/admin/img/icon-clock.svg HTTP/1.1" 304 0
"POST /admin/api/visitor/1/change/ HTTP/1.1" 302 0
"GET /admin/api/visitor/ HTTP/1.1" 200 6505
"GET /admin/jsi18n/ HTTP/1.1" 200 3343
"GET /static/admin/img/icon-yes.svg HTTP/1.1" 304 0
"GET /admin/api/visitor/1/change/ HTTP/1.1" 200 17894
"GET /admin/jsi18n/ HTTP/1.1" 200 3343
Not Found: /media/imgs/test.jpeg
"GET /media/imgs/test.jpeg HTTP/1.1" 404 5369
"GET /admin/api/visitor/1/change/ HTTP/1.1" 200 17894
/Users/tairsairanbekov/PycharmProjects/final/final/urls.py changed, reloading.
Watching for file changes with StatReloader
"GET /media/imgs/test.jpeg HTTP/1.1" 200 282784
"GET /admin/api/visitor/1/change/ HTTP/1.1" 200 17894
/Users/tairsairanbekov/PycharmProjects/final/api/views/cbv.py changed, reloading.
Watching for file changes with StatReloader
/Users/tairsairanbekov/PycharmProjects/final/api/views/vs.py changed, reloading.
Watching for file changes with StatReloader
/Users/tairsairanbekov/PycharmProjects/final/api/views/vs.py changed, reloading.
Watching for file changes with StatReloader
/Users/tairsairanbekov/PycharmProjects/final/api/views/vs.py changed, reloading.
Watching for file changes with StatReloader
Method Not Allowed: /visitors/
"GET /visitors/ HTTP/1.1" 405 40
/Users/tairsairanbekov/PycharmProjects/final/api/views/__init__.py changed, reloading.
Watching for file changes with StatReloader
/Users/tairsairanbekov/PycharmProjects/final/final/urls.py changed, reloading.
Watching for file changes with StatReloader
Method Not Allowed: /visitors/
"GET /visitors/ HTTP/1.1" 405 40
Unauthorized: /manage/
"GET /manage/ HTTP/1.1" 401 58
"POST /login/ HTTP/1.1" 200 483
Unauthorized: /manage/
"GET /manage/ HTTP/1.1" 401 58
Unauthorized: /manage/
"GET /manage/ HTTP/1.1" 401 58
Forbidden: /manage/
"GET /manage/ HTTP/1.1" 403 63
"POST /login/ HTTP/1.1" 200 483
Internal Server Error: /manage/
Traceback (most recent call last):
  File "/Users/tairsairanbekov/PycharmProjects/my_env/lib/python3.9/site-packages/django/core/handlers/exception.py", line 55, in inner
    response = get_response(request)
  File "/Users/tairsairanbekov/PycharmProjects/my_env/lib/python3.9/site-packages/django/core/handlers/base.py", line 197, in _get_response
    response = wrapped_callback(request, *callback_args, **callback_kwargs)
  File "/Users/tairsairanbekov/PycharmProjects/my_env/lib/python3.9/site-packages/django/views/decorators/csrf.py", line 54, in wrapped_view
    return view_func(*args, **kwargs)
  File "/Users/tairsairanbekov/PycharmProjects/my_env/lib/python3.9/site-packages/rest_framework/viewsets.py", line 125, in view
    return self.dispatch(request, *args, **kwargs)
  File "/Users/tairsairanbekov/PycharmProjects/my_env/lib/python3.9/site-packages/rest_framework/views.py", line 509, in dispatch
    response = self.handle_exception(exc)
  File "/Users/tairsairanbekov/PycharmProjects/my_env/lib/python3.9/site-packages/rest_framework/views.py", line 469, in handle_exception
    self.raise_uncaught_exception(exc)
  File "/Users/tairsairanbekov/PycharmProjects/my_env/lib/python3.9/site-packages/rest_framework/views.py", line 480, in raise_uncaught_exception
    raise exc
  File "/Users/tairsairanbekov/PycharmProjects/my_env/lib/python3.9/site-packages/rest_framework/views.py", line 506, in dispatch
    response = handler(request, *args, **kwargs)
  File "/Users/tairsairanbekov/PycharmProjects/final/api/views/vs.py", line 40, in list
    return Response(serializer.data, safe=False)
TypeError: __init__() got an unexpected keyword argument 'safe'
"GET /manage/ HTTP/1.1" 500 87153
Unauthorized: /manage/1/
"DELETE /manage/1/ HTTP/1.1" 401 58
Internal Server Error: /manage/1/
Traceback (most recent call last):
  File "/Users/tairsairanbekov/PycharmProjects/my_env/lib/python3.9/site-packages/django/db/backends/utils.py", line 89, in _execute
    return self.cursor.execute(sql, params)
  File "/Users/tairsairanbekov/PycharmProjects/my_env/lib/python3.9/site-packages/django/db/backends/sqlite3/base.py", line 477, in execute
    return Database.Cursor.execute(self, query, params)
sqlite3.OperationalError: no such table: main.api_visitor__old

The above exception was the direct cause of the following exception:

Traceback (most recent call last):
  File "/Users/tairsairanbekov/PycharmProjects/my_env/lib/python3.9/site-packages/django/core/handlers/exception.py", line 55, in inner
    response = get_response(request)
  File "/Users/tairsairanbekov/PycharmProjects/my_env/lib/python3.9/site-packages/django/core/handlers/base.py", line 197, in _get_response
    response = wrapped_callback(request, *callback_args, **callback_kwargs)
  File "/Users/tairsairanbekov/PycharmProjects/my_env/lib/python3.9/site-packages/django/views/decorators/csrf.py", line 54, in wrapped_view
    return view_func(*args, **kwargs)
  File "/Users/tairsairanbekov/PycharmProjects/my_env/lib/python3.9/site-packages/rest_framework/viewsets.py", line 125, in view
    return self.dispatch(request, *args, **kwargs)
  File "/Users/tairsairanbekov/PycharmProjects/my_env/lib/python3.9/site-packages/rest_framework/views.py", line 509, in dispatch
    response = self.handle_exception(exc)
  File "/Users/tairsairanbekov/PycharmProjects/my_env/lib/python3.9/site-packages/rest_framework/views.py", line 469, in handle_exception
    self.raise_uncaught_exception(exc)
  File "/Users/tairsairanbekov/PycharmProjects/my_env/lib/python3.9/site-packages/rest_framework/views.py", line 480, in raise_uncaught_exception
    raise exc
  File "/Users/tairsairanbekov/PycharmProjects/my_env/lib/python3.9/site-packages/rest_framework/views.py", line 506, in dispatch
    response = handler(request, *args, **kwargs)
  File "/Users/tairsairanbekov/PycharmProjects/final/api/views/vs.py", line 44, in destroy
    user.delete()
  File "/Users/tairsairanbekov/PycharmProjects/my_env/lib/python3.9/site-packages/django/db/models/base.py", line 1094, in delete
    return collector.delete()
  File "/Users/tairsairanbekov/PycharmProjects/my_env/lib/python3.9/site-packages/django/db/models/deletion.py", line 462, in delete
    count = qs._raw_delete(using=self.using)
  File "/Users/tairsairanbekov/PycharmProjects/my_env/lib/python3.9/site-packages/django/db/models/query.py", line 843, in _raw_delete
    cursor = query.get_compiler(using).execute_sql(CURSOR)
  File "/Users/tairsairanbekov/PycharmProjects/my_env/lib/python3.9/site-packages/django/db/models/sql/compiler.py", line 1361, in execute_sql
    cursor.execute(sql, params)
  File "/Users/tairsairanbekov/PycharmProjects/my_env/lib/python3.9/site-packages/django/db/backends/utils.py", line 103, in execute
    return super().execute(sql, params)
  File "/Users/tairsairanbekov/PycharmProjects/my_env/lib/python3.9/site-packages/django/db/backends/utils.py", line 67, in execute
    return self._execute_with_wrappers(
  File "/Users/tairsairanbekov/PycharmProjects/my_env/lib/python3.9/site-packages/django/db/backends/utils.py", line 80, in _execute_with_wrappers
    return executor(sql, params, many, context)
  File "/Users/tairsairanbekov/PycharmProjects/my_env/lib/python3.9/site-packages/django/db/backends/utils.py", line 89, in _execute
    return self.cursor.execute(sql, params)
  File "/Users/tairsairanbekov/PycharmProjects/my_env/lib/python3.9/site-packages/django/db/utils.py", line 91, in __exit__
    raise dj_exc_value.with_traceback(traceback) from exc_value
  File "/Users/tairsairanbekov/PycharmProjects/my_env/lib/python3.9/site-packages/django/db/backends/utils.py", line 89, in _execute
    return self.cursor.execute(sql, params)
  File "/Users/tairsairanbekov/PycharmProjects/my_env/lib/python3.9/site-packages/django/db/backends/sqlite3/base.py", line 477, in execute
    return Database.Cursor.execute(self, query, params)
django.db.utils.OperationalError: no such table: main.api_visitor__old
"DELETE /manage/1/ HTTP/1.1" 500 144385
Internal Server Error: /manage/
Traceback (most recent call last):
  File "/Users/tairsairanbekov/PycharmProjects/my_env/lib/python3.9/site-packages/django/core/handlers/exception.py", line 55, in inner
    response = get_response(request)
  File "/Users/tairsairanbekov/PycharmProjects/my_env/lib/python3.9/site-packages/django/core/handlers/base.py", line 197, in _get_response
    response = wrapped_callback(request, *callback_args, **callback_kwargs)
  File "/Users/tairsairanbekov/PycharmProjects/my_env/lib/python3.9/site-packages/django/views/decorators/csrf.py", line 54, in wrapped_view
    return view_func(*args, **kwargs)
  File "/Users/tairsairanbekov/PycharmProjects/my_env/lib/python3.9/site-packages/rest_framework/viewsets.py", line 125, in view
    return self.dispatch(request, *args, **kwargs)
  File "/Users/tairsairanbekov/PycharmProjects/my_env/lib/python3.9/site-packages/rest_framework/views.py", line 509, in dispatch
    response = self.handle_exception(exc)
  File "/Users/tairsairanbekov/PycharmProjects/my_env/lib/python3.9/site-packages/rest_framework/views.py", line 469, in handle_exception
    self.raise_uncaught_exception(exc)
  File "/Users/tairsairanbekov/PycharmProjects/my_env/lib/python3.9/site-packages/rest_framework/views.py", line 480, in raise_uncaught_exception
    raise exc
  File "/Users/tairsairanbekov/PycharmProjects/my_env/lib/python3.9/site-packages/rest_framework/views.py", line 506, in dispatch
    response = handler(request, *args, **kwargs)
  File "/Users/tairsairanbekov/PycharmProjects/final/api/views/vs.py", line 40, in list
    return Response(serializer.data, safe=False)
TypeError: __init__() got an unexpected keyword argument 'safe'
"GET /manage/ HTTP/1.1" 500 87153
/Users/tairsairanbekov/PycharmProjects/final/api/views/vs.py changed, reloading.
Watching for file changes with StatReloader
"GET /manage/ HTTP/1.1" 200 413
/Users/tairsairanbekov/PycharmProjects/final/api/views/cbv.py changed, reloading.
Watching for file changes with StatReloader
Unauthorized: /login/
"POST /login/ HTTP/1.1" 401 63
"GET /admin/api/visitor/ HTTP/1.1" 200 6310
"GET /admin/api/visitor/5/change/ HTTP/1.1" 200 17734
"GET /admin/jsi18n/ HTTP/1.1" 200 3343
"POST /login/ HTTP/1.1" 200 483
Internal Server Error: /charms/
Traceback (most recent call last):
  File "/Users/tairsairanbekov/PycharmProjects/my_env/lib/python3.9/site-packages/rest_framework/fields.py", line 457, in get_attribute
    return get_attribute(instance, self.source_attrs)
  File "/Users/tairsairanbekov/PycharmProjects/my_env/lib/python3.9/site-packages/rest_framework/fields.py", line 97, in get_attribute
    instance = getattr(instance, attr)
AttributeError: 'Graffiti' object has no attribute 'event'

During handling of the above exception, another exception occurred:

Traceback (most recent call last):
  File "/Users/tairsairanbekov/PycharmProjects/my_env/lib/python3.9/site-packages/django/core/handlers/exception.py", line 55, in inner
    response = get_response(request)
  File "/Users/tairsairanbekov/PycharmProjects/my_env/lib/python3.9/site-packages/django/core/handlers/base.py", line 197, in _get_response
    response = wrapped_callback(request, *callback_args, **callback_kwargs)
  File "/Users/tairsairanbekov/PycharmProjects/my_env/lib/python3.9/site-packages/django/views/decorators/csrf.py", line 54, in wrapped_view
    return view_func(*args, **kwargs)
  File "/Users/tairsairanbekov/PycharmProjects/my_env/lib/python3.9/site-packages/rest_framework/viewsets.py", line 125, in view
    return self.dispatch(request, *args, **kwargs)
  File "/Users/tairsairanbekov/PycharmProjects/my_env/lib/python3.9/site-packages/rest_framework/views.py", line 509, in dispatch
    response = self.handle_exception(exc)
  File "/Users/tairsairanbekov/PycharmProjects/my_env/lib/python3.9/site-packages/rest_framework/views.py", line 469, in handle_exception
    self.raise_uncaught_exception(exc)
  File "/Users/tairsairanbekov/PycharmProjects/my_env/lib/python3.9/site-packages/rest_framework/views.py", line 480, in raise_uncaught_exception
    raise exc
  File "/Users/tairsairanbekov/PycharmProjects/my_env/lib/python3.9/site-packages/rest_framework/views.py", line 506, in dispatch
    response = handler(request, *args, **kwargs)
  File "/Users/tairsairanbekov/PycharmProjects/final/api/views/vs.py", line 46, in list
    return Response(serializer.data)
  File "/Users/tairsairanbekov/PycharmProjects/my_env/lib/python3.9/site-packages/rest_framework/serializers.py", line 768, in data
    ret = super().data
  File "/Users/tairsairanbekov/PycharmProjects/my_env/lib/python3.9/site-packages/rest_framework/serializers.py", line 253, in data
    self._data = self.to_representation(self.instance)
  File "/Users/tairsairanbekov/PycharmProjects/my_env/lib/python3.9/site-packages/rest_framework/serializers.py", line 686, in to_representation
    return [
  File "/Users/tairsairanbekov/PycharmProjects/my_env/lib/python3.9/site-packages/rest_framework/serializers.py", line 687, in <listcomp>
    self.child.to_representation(item) for item in iterable
  File "/Users/tairsairanbekov/PycharmProjects/my_env/lib/python3.9/site-packages/rest_framework/serializers.py", line 509, in to_representation
    attribute = field.get_attribute(instance)
  File "/Users/tairsairanbekov/PycharmProjects/my_env/lib/python3.9/site-packages/rest_framework/fields.py", line 490, in get_attribute
    raise type(exc)(msg)
AttributeError: Got AttributeError when attempting to get a value for field `event` on serializer `CharmSerializer`.
The serializer field might be named incorrectly and not match any attribute or key on the `Graffiti` instance.
Original exception text was: 'Graffiti' object has no attribute 'event'.
"GET /charms/ HTTP/1.1" 500 122575
/Users/tairsairanbekov/PycharmProjects/final/api/views/vs.py changed, reloading.
Watching for file changes with StatReloader
"GET /charms/ HTTP/1.1" 200 75
/Users/tairsairanbekov/PycharmProjects/final/api/views/__init__.py changed, reloading.
Watching for file changes with StatReloader
"GET /charms/ HTTP/1.1" 200 75
Unauthorized: /charms/1/
"GET /charms/1/ HTTP/1.1" 401 58
"POST /login/ HTTP/1.1" 200 483
Unauthorized: /charms/1/
"GET /charms/1/ HTTP/1.1" 401 58
Forbidden: /charms/1/
"GET /charms/1/ HTTP/1.1" 403 63
"GET /charms/ HTTP/1.1" 200 75
Method Not Allowed: /charms/
"POST /charms/ HTTP/1.1" 405 41
/Users/tairsairanbekov/PycharmProjects/final/final/urls.py changed, reloading.
Watching for file changes with StatReloader
Not Found: /charms/1/
"GET /charms/1/ HTTP/1.1" 404 6504
Unauthorized: /charmsdetail/
"POST /charmsdetail/ HTTP/1.1" 401 58
"POST /login/ HTTP/1.1" 200 483
Unauthorized: /charmsdetail/
"POST /charmsdetail/ HTTP/1.1" 401 58
Forbidden: /charmsdetail/
"POST /charmsdetail/ HTTP/1.1" 403 63
Not Found: /charms/1/
"PATCH /charms/1/ HTTP/1.1" 404 6506
Forbidden: /charmsdetail/1/
"PATCH /charmsdetail/1/ HTTP/1.1" 403 63
/Users/tairsairanbekov/PycharmProjects/final/api/views/vs.py changed, reloading.
Watching for file changes with StatReloader
"POST /login/ HTTP/1.1" 200 483
"GET /charms/ HTTP/1.1" 200 75
Not Found: /charms/1/
"GET /charms/1/ HTTP/1.1" 404 23
"GET /charms/2/ HTTP/1.1" 200 73
/Users/tairsairanbekov/PycharmProjects/final/api/views/cbv.py changed, reloading.
Watching for file changes with StatReloader
/Users/tairsairanbekov/PycharmProjects/final/api/views/vs.py changed, reloading.
Watching for file changes with StatReloader
/Users/tairsairanbekov/PycharmProjects/final/api/views/vs.py changed, reloading.
Watching for file changes with StatReloader
Unauthorized: /graffitiesdetail/1/
"PATCH /graffitiesdetail/1/ HTTP/1.1" 401 183
"POST /login/ HTTP/1.1" 200 483
{'price': [ErrorDetail(string='This field is required.', code='required')], 'image': [ErrorDetail(string='This field is required.', code='required')], 'isAnimated': [ErrorDetail(string='This field is required.', code='required')]}
"PATCH /graffitiesdetail/1/ HTTP/1.1" 200 114
Bad Request: /graffitiesdetail/1/
"PATCH /graffitiesdetail/1/ HTTP/1.1" 400 82
"PATCH /graffitiesdetail/1/ HTTP/1.1" 200 68
Graffities sent
"GET /graffities/ HTTP/1.1" 200 141
Graffiti sent
"GET /graffities/1/ HTTP/1.1" 200 68
Unauthorized: /graffitiesdetail/
"POST /graffitiesdetail/ HTTP/1.1" 401 58
Internal Server Error: /charmsdetail/1/
Traceback (most recent call last):
  File "/Users/tairsairanbekov/PycharmProjects/my_env/lib/python3.9/site-packages/django/core/handlers/exception.py", line 55, in inner
    response = get_response(request)
  File "/Users/tairsairanbekov/PycharmProjects/my_env/lib/python3.9/site-packages/django/core/handlers/base.py", line 197, in _get_response
    response = wrapped_callback(request, *callback_args, **callback_kwargs)
  File "/Users/tairsairanbekov/PycharmProjects/my_env/lib/python3.9/site-packages/django/views/decorators/csrf.py", line 54, in wrapped_view
    return view_func(*args, **kwargs)
  File "/Users/tairsairanbekov/PycharmProjects/my_env/lib/python3.9/site-packages/rest_framework/viewsets.py", line 125, in view
    return self.dispatch(request, *args, **kwargs)
  File "/Users/tairsairanbekov/PycharmProjects/my_env/lib/python3.9/site-packages/rest_framework/views.py", line 509, in dispatch
    response = self.handle_exception(exc)
  File "/Users/tairsairanbekov/PycharmProjects/my_env/lib/python3.9/site-packages/rest_framework/views.py", line 469, in handle_exception
    self.raise_uncaught_exception(exc)
  File "/Users/tairsairanbekov/PycharmProjects/my_env/lib/python3.9/site-packages/rest_framework/views.py", line 480, in raise_uncaught_exception
    raise exc
  File "/Users/tairsairanbekov/PycharmProjects/my_env/lib/python3.9/site-packages/rest_framework/views.py", line 506, in dispatch
    response = handler(request, *args, **kwargs)
  File "/Users/tairsairanbekov/PycharmProjects/final/api/views/vs.py", line 89, in partial_update
    charm = Charm.objects.get(id=pk)
  File "/Users/tairsairanbekov/PycharmProjects/my_env/lib/python3.9/site-packages/django/db/models/manager.py", line 85, in manager_method
    return getattr(self.get_queryset(), name)(*args, **kwargs)
  File "/Users/tairsairanbekov/PycharmProjects/my_env/lib/python3.9/site-packages/django/db/models/query.py", line 496, in get
    raise self.model.DoesNotExist(
api.models.Charm.DoesNotExist: Charm matching query does not exist.
"PATCH /charmsdetail/1/ HTTP/1.1" 500 95402
{'price': [ErrorDetail(string='This field is required.', code='required')], 'image': [ErrorDetail(string='This field is required.', code='required')], 'event': [ErrorDetail(string='This field is required.', code='required')]}
"PATCH /charmsdetail/2/ HTTP/1.1" 200 109
"PATCH /charmsdetail/2/ HTTP/1.1" 200 79
Charm sent
"GET /charms/2/ HTTP/1.1" 200 79
Charms sent
"GET /charms/ HTTP/1.1" 200 81
Not Found: /ski
"PUT /ski HTTP/1.1" 404 7504
Method Not Allowed: /skins/1/
"PUT /skins/1/ HTTP/1.1" 405 40
Method Not Allowed: /skins/1/
"PATCH /skins/1/ HTTP/1.1" 405 42
Method Not Allowed: /skins/1/
"PUT /skins/1/ HTTP/1.1" 405 40
/Users/tairsairanbekov/PycharmProjects/final/api/views/cbv.py changed, reloading.
Watching for file changes with StatReloader
Method Not Allowed: /skins/1/
"PUT /skins/1/ HTTP/1.1" 405 40
Method Not Allowed: /skins/1/
"PUT /skins/1/ HTTP/1.1" 405 40
Skins sent
"GET /skins/1/ HTTP/1.1" 200 452
/Users/tairsairanbekov/PycharmProjects/final/final/urls.py changed, reloading.
Watching for file changes with StatReloader
Unauthorized: /skins/1/edit
"GET /skins/1/edit HTTP/1.1" 401 58
"POST /login/ HTTP/1.1" 200 483
Internal Server Error: /skins/1/edit
Traceback (most recent call last):
  File "/Users/tairsairanbekov/PycharmProjects/my_env/lib/python3.9/site-packages/django/core/handlers/exception.py", line 55, in inner
    response = get_response(request)
  File "/Users/tairsairanbekov/PycharmProjects/my_env/lib/python3.9/site-packages/django/core/handlers/base.py", line 197, in _get_response
    response = wrapped_callback(request, *callback_args, **callback_kwargs)
  File "/Users/tairsairanbekov/PycharmProjects/my_env/lib/python3.9/site-packages/django/views/decorators/csrf.py", line 54, in wrapped_view
    return view_func(*args, **kwargs)
  File "/Users/tairsairanbekov/PycharmProjects/my_env/lib/python3.9/site-packages/django/views/generic/base.py", line 84, in view
    return self.dispatch(request, *args, **kwargs)
  File "/Users/tairsairanbekov/PycharmProjects/my_env/lib/python3.9/site-packages/rest_framework/views.py", line 509, in dispatch
    response = self.handle_exception(exc)
  File "/Users/tairsairanbekov/PycharmProjects/my_env/lib/python3.9/site-packages/rest_framework/views.py", line 469, in handle_exception
    self.raise_uncaught_exception(exc)
  File "/Users/tairsairanbekov/PycharmProjects/my_env/lib/python3.9/site-packages/rest_framework/views.py", line 480, in raise_uncaught_exception
    raise exc
  File "/Users/tairsairanbekov/PycharmProjects/my_env/lib/python3.9/site-packages/rest_framework/views.py", line 506, in dispatch
    response = handler(request, *args, **kwargs)
TypeError: get() got multiple values for argument 'skin_id'
"GET /skins/1/edit HTTP/1.1" 500 82358
Not Found: /skins/1/edit/
"GET /skins/1/edit/ HTTP/1.1" 404 7538
/Users/tairsairanbekov/PycharmProjects/final/final/urls.py changed, reloading.
Watching for file changes with StatReloader
Internal Server Error: /skins/1/edit/
Traceback (most recent call last):
  File "/Users/tairsairanbekov/PycharmProjects/my_env/lib/python3.9/site-packages/django/core/handlers/exception.py", line 55, in inner
    response = get_response(request)
  File "/Users/tairsairanbekov/PycharmProjects/my_env/lib/python3.9/site-packages/django/core/handlers/base.py", line 197, in _get_response
    response = wrapped_callback(request, *callback_args, **callback_kwargs)
  File "/Users/tairsairanbekov/PycharmProjects/my_env/lib/python3.9/site-packages/django/views/decorators/csrf.py", line 54, in wrapped_view
    return view_func(*args, **kwargs)
  File "/Users/tairsairanbekov/PycharmProjects/my_env/lib/python3.9/site-packages/django/views/generic/base.py", line 84, in view
    return self.dispatch(request, *args, **kwargs)
  File "/Users/tairsairanbekov/PycharmProjects/my_env/lib/python3.9/site-packages/rest_framework/views.py", line 509, in dispatch
    response = self.handle_exception(exc)
  File "/Users/tairsairanbekov/PycharmProjects/my_env/lib/python3.9/site-packages/rest_framework/views.py", line 469, in handle_exception
    self.raise_uncaught_exception(exc)
  File "/Users/tairsairanbekov/PycharmProjects/my_env/lib/python3.9/site-packages/rest_framework/views.py", line 480, in raise_uncaught_exception
    raise exc
  File "/Users/tairsairanbekov/PycharmProjects/my_env/lib/python3.9/site-packages/rest_framework/views.py", line 506, in dispatch
    response = handler(request, *args, **kwargs)
TypeError: get() got multiple values for argument 'skin_id'
"GET /skins/1/edit/ HTTP/1.1" 500 82373
/Users/tairsairanbekov/PycharmProjects/final/final/urls.py changed, reloading.
Watching for file changes with StatReloader
/Users/tairsairanbekov/PycharmProjects/final/final/urls.py changed, reloading.
Watching for file changes with StatReloader
Internal Server Error: /skins/1/
Traceback (most recent call last):
  File "/Users/tairsairanbekov/PycharmProjects/my_env/lib/python3.9/site-packages/django/core/handlers/exception.py", line 55, in inner
    response = get_response(request)
  File "/Users/tairsairanbekov/PycharmProjects/my_env/lib/python3.9/site-packages/django/core/handlers/base.py", line 197, in _get_response
    response = wrapped_callback(request, *callback_args, **callback_kwargs)
  File "/Users/tairsairanbekov/PycharmProjects/my_env/lib/python3.9/site-packages/django/views/decorators/csrf.py", line 54, in wrapped_view
    return view_func(*args, **kwargs)
  File "/Users/tairsairanbekov/PycharmProjects/my_env/lib/python3.9/site-packages/django/views/generic/base.py", line 84, in view
    return self.dispatch(request, *args, **kwargs)
  File "/Users/tairsairanbekov/PycharmProjects/my_env/lib/python3.9/site-packages/rest_framework/views.py", line 509, in dispatch
    response = self.handle_exception(exc)
  File "/Users/tairsairanbekov/PycharmProjects/my_env/lib/python3.9/site-packages/rest_framework/views.py", line 469, in handle_exception
    self.raise_uncaught_exception(exc)
  File "/Users/tairsairanbekov/PycharmProjects/my_env/lib/python3.9/site-packages/rest_framework/views.py", line 480, in raise_uncaught_exception
    raise exc
  File "/Users/tairsairanbekov/PycharmProjects/my_env/lib/python3.9/site-packages/rest_framework/views.py", line 506, in dispatch
    response = handler(request, *args, **kwargs)
TypeError: get() got multiple values for argument 'skin_id'
"GET /skins/1/ HTTP/1.1" 500 82298
Internal Server Error: /skins/1/
Traceback (most recent call last):
  File "/Users/tairsairanbekov/PycharmProjects/my_env/lib/python3.9/site-packages/django/core/handlers/exception.py", line 55, in inner
    response = get_response(request)
  File "/Users/tairsairanbekov/PycharmProjects/my_env/lib/python3.9/site-packages/django/core/handlers/base.py", line 197, in _get_response
    response = wrapped_callback(request, *callback_args, **callback_kwargs)
  File "/Users/tairsairanbekov/PycharmProjects/my_env/lib/python3.9/site-packages/django/views/decorators/csrf.py", line 54, in wrapped_view
    return view_func(*args, **kwargs)
  File "/Users/tairsairanbekov/PycharmProjects/my_env/lib/python3.9/site-packages/django/views/generic/base.py", line 84, in view
    return self.dispatch(request, *args, **kwargs)
  File "/Users/tairsairanbekov/PycharmProjects/my_env/lib/python3.9/site-packages/rest_framework/views.py", line 509, in dispatch
    response = self.handle_exception(exc)
  File "/Users/tairsairanbekov/PycharmProjects/my_env/lib/python3.9/site-packages/rest_framework/views.py", line 469, in handle_exception
    self.raise_uncaught_exception(exc)
  File "/Users/tairsairanbekov/PycharmProjects/my_env/lib/python3.9/site-packages/rest_framework/views.py", line 480, in raise_uncaught_exception
    raise exc
  File "/Users/tairsairanbekov/PycharmProjects/my_env/lib/python3.9/site-packages/rest_framework/views.py", line 506, in dispatch
    response = handler(request, *args, **kwargs)
TypeError: get() got multiple values for argument 'skin_id'
"GET /skins/1/ HTTP/1.1" 500 82306
{'price': [ErrorDetail(string='This field is required.', code='required')], 'image': [ErrorDetail(string='This field is required.', code='required')], 'rarity': [ErrorDetail(string='This field is required.', code='required')], 'enchantment': [ErrorDetail(string='This field is required.', code='required')], 'gun': [ErrorDetail(string='This field is required.', code='required')]}
"PUT /skins/1/ HTTP/1.1" 200 186
/Users/tairsairanbekov/PycharmProjects/final/api/views/cbv.py changed, reloading.
Watching for file changes with StatReloader
Skins sent
"GET /skins/?q=haha HTTP/1.1" 200 452
/Users/tairsairanbekov/PycharmProjects/final/api/views/cbv.py changed, reloading.
Watching for file changes with StatReloader
Skins sent
"GET /skins/?q=all HTTP/1.1" 200 452
Skins sent
"GET /skins/?q=XE HTTP/1.1" 200 452
Skins sent
"GET /skins/?q=SE HTTP/1.1" 200 2
Unauthorized: /blogs/1/
"DELETE /blogs/1/ HTTP/1.1" 401 58
Unauthorized: /blogs/1/
"DELETE /blogs/1/ HTTP/1.1" 401 183
"POST /login/ HTTP/1.1" 200 483
Internal Server Error: /blogs/1/
Traceback (most recent call last):
  File "/Users/tairsairanbekov/PycharmProjects/my_env/lib/python3.9/site-packages/django/core/handlers/exception.py", line 55, in inner
    response = get_response(request)
  File "/Users/tairsairanbekov/PycharmProjects/my_env/lib/python3.9/site-packages/django/core/handlers/base.py", line 197, in _get_response
    response = wrapped_callback(request, *callback_args, **callback_kwargs)
  File "/Users/tairsairanbekov/PycharmProjects/my_env/lib/python3.9/site-packages/django/views/decorators/csrf.py", line 54, in wrapped_view
    return view_func(*args, **kwargs)
  File "/Users/tairsairanbekov/PycharmProjects/my_env/lib/python3.9/site-packages/django/views/generic/base.py", line 84, in view
    return self.dispatch(request, *args, **kwargs)
  File "/Users/tairsairanbekov/PycharmProjects/my_env/lib/python3.9/site-packages/rest_framework/views.py", line 509, in dispatch
    response = self.handle_exception(exc)
  File "/Users/tairsairanbekov/PycharmProjects/my_env/lib/python3.9/site-packages/rest_framework/views.py", line 469, in handle_exception
    self.raise_uncaught_exception(exc)
  File "/Users/tairsairanbekov/PycharmProjects/my_env/lib/python3.9/site-packages/rest_framework/views.py", line 480, in raise_uncaught_exception
    raise exc
  File "/Users/tairsairanbekov/PycharmProjects/my_env/lib/python3.9/site-packages/rest_framework/views.py", line 506, in dispatch
    response = handler(request, *args, **kwargs)
TypeError: delete() got multiple values for argument 'blog_id'
"DELETE /blogs/1/ HTTP/1.1" 500 82355
{'price': [ErrorDetail(string='This field is required.', code='required')], 'image': [ErrorDetail(string='This field is required.', code='required')], 'rarity': [ErrorDetail(string='This field is required.', code='required')], 'enchantment': [ErrorDetail(string='This field is required.', code='required')], 'gun': [ErrorDetail(string='This field is required.', code='required')]}
"PUT /skins/1/ HTTP/1.1" 200 186
"PUT /blogs/1/ HTTP/1.1" 200 50
/Users/tairsairanbekov/PycharmProjects/final/api/views/cbv.py changed, reloading.
Watching for file changes with StatReloader
Internal Server Error: /blogs/1/
Traceback (most recent call last):
  File "/Users/tairsairanbekov/PycharmProjects/my_env/lib/python3.9/site-packages/django/core/handlers/exception.py", line 55, in inner
    response = get_response(request)
  File "/Users/tairsairanbekov/PycharmProjects/my_env/lib/python3.9/site-packages/django/core/handlers/base.py", line 197, in _get_response
    response = wrapped_callback(request, *callback_args, **callback_kwargs)
  File "/Users/tairsairanbekov/PycharmProjects/my_env/lib/python3.9/site-packages/django/views/decorators/csrf.py", line 54, in wrapped_view
    return view_func(*args, **kwargs)
  File "/Users/tairsairanbekov/PycharmProjects/my_env/lib/python3.9/site-packages/django/views/generic/base.py", line 84, in view
    return self.dispatch(request, *args, **kwargs)
  File "/Users/tairsairanbekov/PycharmProjects/my_env/lib/python3.9/site-packages/rest_framework/views.py", line 509, in dispatch
    response = self.handle_exception(exc)
  File "/Users/tairsairanbekov/PycharmProjects/my_env/lib/python3.9/site-packages/rest_framework/views.py", line 469, in handle_exception
    self.raise_uncaught_exception(exc)
  File "/Users/tairsairanbekov/PycharmProjects/my_env/lib/python3.9/site-packages/rest_framework/views.py", line 480, in raise_uncaught_exception
    raise exc
  File "/Users/tairsairanbekov/PycharmProjects/my_env/lib/python3.9/site-packages/rest_framework/views.py", line 506, in dispatch
    response = handler(request, *args, **kwargs)
TypeError: delete() got multiple values for argument 'blog_id'
"DELETE /blogs/1/ HTTP/1.1" 500 82355
/Users/tairsairanbekov/PycharmProjects/final/api/views/cbv.py changed, reloading.
Watching for file changes with StatReloader
Internal Server Error: /blogs/1/
Traceback (most recent call last):
  File "/Users/tairsairanbekov/PycharmProjects/my_env/lib/python3.9/site-packages/django/core/handlers/exception.py", line 55, in inner
    response = get_response(request)
  File "/Users/tairsairanbekov/PycharmProjects/my_env/lib/python3.9/site-packages/django/core/handlers/base.py", line 197, in _get_response
    response = wrapped_callback(request, *callback_args, **callback_kwargs)
  File "/Users/tairsairanbekov/PycharmProjects/my_env/lib/python3.9/site-packages/django/views/decorators/csrf.py", line 54, in wrapped_view
    return view_func(*args, **kwargs)
  File "/Users/tairsairanbekov/PycharmProjects/my_env/lib/python3.9/site-packages/django/views/generic/base.py", line 84, in view
    return self.dispatch(request, *args, **kwargs)
  File "/Users/tairsairanbekov/PycharmProjects/my_env/lib/python3.9/site-packages/rest_framework/views.py", line 509, in dispatch
    response = self.handle_exception(exc)
  File "/Users/tairsairanbekov/PycharmProjects/my_env/lib/python3.9/site-packages/rest_framework/views.py", line 469, in handle_exception
    self.raise_uncaught_exception(exc)
  File "/Users/tairsairanbekov/PycharmProjects/my_env/lib/python3.9/site-packages/rest_framework/views.py", line 480, in raise_uncaught_exception
    raise exc
  File "/Users/tairsairanbekov/PycharmProjects/my_env/lib/python3.9/site-packages/rest_framework/views.py", line 506, in dispatch
    response = handler(request, *args, **kwargs)
TypeError: delete() got multiple values for argument 'blog_id'
"DELETE /blogs/1/ HTTP/1.1" 500 82355
/Users/tairsairanbekov/PycharmProjects/final/api/views/cbv.py changed, reloading.
Watching for file changes with StatReloader
Unauthorized: /blogs/
"GET /blogs/ HTTP/1.1" 401 58
Unauthorized: /blogs/
"GET /blogs/ HTTP/1.1" 401 183
"POST /login/ HTTP/1.1" 200 483
Blogs sent
"GET /blogs/ HTTP/1.1" 200 52
Internal Server Error: /blogs/1/
Traceback (most recent call last):
  File "/Users/tairsairanbekov/PycharmProjects/my_env/lib/python3.9/site-packages/django/core/handlers/exception.py", line 55, in inner
    response = get_response(request)
  File "/Users/tairsairanbekov/PycharmProjects/my_env/lib/python3.9/site-packages/django/core/handlers/base.py", line 197, in _get_response
    response = wrapped_callback(request, *callback_args, **callback_kwargs)
  File "/Users/tairsairanbekov/PycharmProjects/my_env/lib/python3.9/site-packages/django/views/decorators/csrf.py", line 54, in wrapped_view
    return view_func(*args, **kwargs)
  File "/Users/tairsairanbekov/PycharmProjects/my_env/lib/python3.9/site-packages/django/views/generic/base.py", line 84, in view
    return self.dispatch(request, *args, **kwargs)
  File "/Users/tairsairanbekov/PycharmProjects/my_env/lib/python3.9/site-packages/rest_framework/views.py", line 509, in dispatch
    response = self.handle_exception(exc)
  File "/Users/tairsairanbekov/PycharmProjects/my_env/lib/python3.9/site-packages/rest_framework/views.py", line 469, in handle_exception
    self.raise_uncaught_exception(exc)
  File "/Users/tairsairanbekov/PycharmProjects/my_env/lib/python3.9/site-packages/rest_framework/views.py", line 480, in raise_uncaught_exception
    raise exc
  File "/Users/tairsairanbekov/PycharmProjects/my_env/lib/python3.9/site-packages/rest_framework/views.py", line 506, in dispatch
    response = handler(request, *args, **kwargs)
TypeError: delete() got multiple values for argument 'blog_id'
"DELETE /blogs/1/ HTTP/1.1" 500 82355
Unauthorized: /skins/1/
"DELETE /skins/1/ HTTP/1.1" 401 58
Internal Server Error: /skins/1/
Traceback (most recent call last):
  File "/Users/tairsairanbekov/PycharmProjects/my_env/lib/python3.9/site-packages/django/core/handlers/exception.py", line 55, in inner
    response = get_response(request)
  File "/Users/tairsairanbekov/PycharmProjects/my_env/lib/python3.9/site-packages/django/core/handlers/base.py", line 197, in _get_response
    response = wrapped_callback(request, *callback_args, **callback_kwargs)
  File "/Users/tairsairanbekov/PycharmProjects/my_env/lib/python3.9/site-packages/django/views/decorators/csrf.py", line 54, in wrapped_view
    return view_func(*args, **kwargs)
  File "/Users/tairsairanbekov/PycharmProjects/my_env/lib/python3.9/site-packages/django/views/generic/base.py", line 84, in view
    return self.dispatch(request, *args, **kwargs)
  File "/Users/tairsairanbekov/PycharmProjects/my_env/lib/python3.9/site-packages/rest_framework/views.py", line 509, in dispatch
    response = self.handle_exception(exc)
  File "/Users/tairsairanbekov/PycharmProjects/my_env/lib/python3.9/site-packages/rest_framework/views.py", line 469, in handle_exception
    self.raise_uncaught_exception(exc)
  File "/Users/tairsairanbekov/PycharmProjects/my_env/lib/python3.9/site-packages/rest_framework/views.py", line 480, in raise_uncaught_exception
    raise exc
  File "/Users/tairsairanbekov/PycharmProjects/my_env/lib/python3.9/site-packages/rest_framework/views.py", line 506, in dispatch
    response = handler(request, *args, **kwargs)
TypeError: delete() got multiple values for argument 'skin_id'
"DELETE /skins/1/ HTTP/1.1" 500 82355
/Users/tairsairanbekov/PycharmProjects/final/api/views/cbv.py changed, reloading.
Watching for file changes with StatReloader
Skin deleted
"DELETE /skins/1/ HTTP/1.1" 204 21
Blog deleted
"DELETE /blogs/1/ HTTP/1.1" 204 21
Blogs sent
"GET /blogs/ HTTP/1.1" 200 2
Skins sent
"GET /skins/?q=SE HTTP/1.1" 200 2
Skins sent
"GET /skins/?q=SE HTTP/1.1" 200 2
Skins sent
"GET /skins/?q=all HTTP/1.1" 200 227
